Workbook
Name CN_conversion_method: 'Cap Table'!$C$19
Name CN_table: 'Cap Table'!$G$13:$H$26
Name CN1_cap: 'Cap Table'!$G$16
Name CN1_disc: 'Cap Table'!$G$15
Name CN1_disccap: 'Cap Table'!$G$22
Name CN1_invested: 'Cap Table'!$G$18
Name CN1_value: 'Cap Table'!$G$19
Name CN2_cap: 'Cap Table'!$H$16
Name CN2_disc: 'Cap Table'!$H$15
Name CN2_disccap: 'Cap Table'!$H$22
Name CN2_invested: 'Cap Table'!$H$18
Name CN2_value: 'Cap Table'!$H$19
Name inputs: 'Cap Table'!$C$13:$C$27
Name investment_date: 'Cap Table'!$C$27
Name issue_share_price: 'Cap Table'!$C$26
Name new_money: 'Cap Table'!$C$16
Name optionholder_shares: 'Cap Table'!$E$74
Name post_money_option_pool: 'Cap Table'!$C$22
Name post_money_valuation: 'Cap Table'!$C$20
Name pre_money: 'Cap Table'!$C$21
Name pre_money_valuation: 'Cap Table'!$C$21
Name share_classes: Lists!$D$12:$D$15
Name shareholder_shares: 'Cap Table'!$E$33

Sheet Title
B6: LegalVision's Pro Forma Capitalisation Table and Model
B8: Legend
B10: Input
B11: Calculation
B12: Total
B14: Contents
B16: Instructions | D16: Explanation of how to use this spreadsheet.
B17: Capitalisation Table | D17: Complete list of shareholders and model to evaluate impact of a simple future funding round.
B19: Find out more
B21: For more information, please contact LegalVision
B23: p | C23: 1300 544 755
B24: w | C24: www.legalvision.com.au
B25: e | C25: captable@legalvision.com.au
B26: a | C26: 100 Harris Street, Pyrmont NSW 2009

Sheet Instructions
B5: Instructions
B7: Disclaimer: | C7: This is a pro-forma generic spreadsheet and you should not rely on it for making any decisions.
C8: You should seek legal, financial and other professional advice regarding your individual situation.
B10: Please note that every company is different and you should consider carefuly whether this model is appropriate for you.
B11: In particular, the terms of any non-ordinary shares or notes are likely not to match the plain vanilla ones modelled exactly (and may have vastly different characteristics).
B13: What is a Capitalisation Table?
B15: A capitalisation table, or cap table, is a spreadsheet that sets out who owns shares (or rights to shares) in a company.
B16: It is a complete record of the founders' and investors' share and option holdings and any convertible instruments.
B17: This spreadsheet includes a model for calculating the impact on your company and shareholders of raising new capital.
B19: How to Use This Spreadsheet
B20: Description: | C20: The Capitalisation Table tab is a complete list of shareholders and their holdings, before and after a capital raising round.
B22: Glossary: | C22: To assist you in using this cap table, there explanations throughout for certain terms. If you hover over the cells with red triangles, there are comments which explain the relevant term.
B24: Help: | C24: There are many articles on our website on this and related issues that may give you additional insight. Go to www.legalvision.com.au.
C25: If you have any questions or suggestions please email us at captable@legalvision.com.au.

Sheet Cap Table
A1: WINAY - LAEF HEALTH AND WELLNESS RESORT GROUP
B5: Inputs
B6: Company Name In Australia | C6: PMG Pty Ltd
B7: Company Name In Australia | C7: Haycar Investments Pty Ltd
B8: Company Name In Abu Dhabi | C8: PMG JV HAYCAR TECH Pty Ltd
B9: Company Name In Vanuatu | C9: PMG & Haycar Global
B10: Company Name In Vanuatu | C10: Laef Health & Wellness Resort Group
B11: Company Name In Peru | C11: Haycar Global PE
B12: Company Name In Peru | C12: Winay Wasi Health & Wellness Resort Group | F12: Convertible Instruments
G13: Con Inst 1 | H13: Con Inst 2
F14: Interest rate | G14: 0 | H14: 0
B15: Pre-money agreed valuation | C15: 5000000 | F15: Discount | G15: 0.2 | H15: 0.2
B16: New money | C16: =J33+J45 -> 1000000 | F16: Valuation Cap | G16: 4000000 | H16: 4000000
B17: Con inst 1 value | C17: =G23 -> 375000 | F17: Date issued | G17: 44129 | H17: 44195
B18: Con inst 2 value | C18: =H23 -> 250000 | F18: Total invested | G18: =SUMIF($C$63:$C$72,G13,$E$63:$E$72) -> 300000 | H18: =SUMIF($C$63:$C$72,H13,$E$63:$E$72) -> 200000
B19: Con inst conversion method | C19: Post-money | F19: With acc. interest | G19: =G18*(1+(G14*(investment_date-G17)/365)) -> 300000 | H19: =H18*(1+(H14*(investment_date-H17)/365)) -> 200000
B20: Deemed post-money (assuming con inst) | C20: =IF(CN_conversion_method=Lists!B25,SUM(C15:C18),IF(CN_conversion_method=Lists!B26,SUM(C15:C16),IF(CN_conversion_method=Lists!B27,SUM(C15:C16)+SUM(G18:H18),"Error"))) -> 6000000 | F20: Using discount | G20: =G19/(1-G15) -> 375000 | H20: =H19/(1-H15) -> 250000
B21: Deemed pre-money (assuming con inst) | C21: =C20-SUM(C16:C18) -> 4375000 | F21: Using cap | G21: =IF(G16=0,0,G19/(G16/$C$15)) -> 375000 | H21: =IF(H16=0,0,H19/(H16/$C$15)) -> 250000
B22: Post investment ESOP (%) | C22: 0.1 | F22: Discount or cap | G22: =IF(G20<G21,"Cap","Disc") -> Disc | H22: =IF(H20<H21,"Cap","Disc") -> Disc
B23: Post inv ESOP % additional or inclusive | C23: % additional | E23: =IF(AND(ROUND(IF(C23="% includes current",Lists!D48,IF(C23="% additional",Lists!D47,"Error")),0)<0,C23="% includes current"),"Post > Current","") | F23: Conv value | G23: =MAX(G20:G21) -> 375000 | H23: =MAX(H20:H21) -> 250000
B24: Post investment ESOP (number) | C24: =O84 -> 174834 | F24: Issue price used | G24: =issue_share_price -> 3.4318 | H24: =issue_share_price -> 3.4318
B25: Deemed pre-money (assuming con inst & ESOP) | C25: =C21-N84 -> 3775004.7 | F25: Conv price | G25: =IF(G22="Disc", G24*(1-G15),G24 * G16 / $C15) -> 2.74544 | H25: =IF(H22="Disc", H24*(1-H15),H24 * H16 / $C15) -> 2.74544
B26: Investment price per share | C26: =IF(E87=0,"N/a",ROUND(C21/(E87+O84),4)) -> 3.4318 | F26: Conv shares | G26: =G19/G25 -> 109272.1 | H26: =H19/H25 -> 72848.068
B27: Investment date | C27: 44377
B29: Capitalisation Table
E30: Current members, option and note holders | J30: Investments | N30: Post-investment
B31: Shareholder | C31: Class | E31: Number of shares (#) and inst value ($) | F31: Holding (undiluted) | G31: Holding (diluted) | H31: Pre-money value ($) | J31: Notional Investment ($) | K31: Number (#) | L31: %age of this investment round | N31: Post-money val/ Actual investment ($) | O31: Number of shares (#) | P31: Holding (undiluted) | Q31: Holding (fully diluted)
B33: Current shareholders | E33: =SUM(E34:E43) -> 1000000 | F33: =SUM(F34:F43) -> 1 | G33: =SUM(G34:G43) -> 0.90909091 | H33: =SUM(H34:H43) -> 4545454.5 | J33: =SUM(J34:J43) -> 0 | K33: =SUM(K34:K43) -> 0 | L33: =SUM(L34:L43) -> 0 | N33: =SUM(N34:N43) -> 3431800 | O33: =SUM(O34:O43) -> 1000000 | P33: =SUM(P34:P43) -> 0.67865073 | Q33: =SUM(Q34:Q43) -> 0.57196916
B34: Shareholder #1 | C34: Ordinary (ORD) | E34: 1000000 | F34: =E34/$E$86 -> 1 | G34: =E34/$E$87 -> 0.90909091 | H34: =G34*$C$15 -> 4545454.5 | J34: 0 | K34: =ROUND(J34/issue_share_price,0) -> 0 | L34: =IF($K$86=0,0,K34/$K$86) -> 0 | N34: =ROUND(O34*issue_share_price,2) -> 3431800 | O34: =E34+K34 -> 1000000 | P34: =O34/$O$86 -> 0.67865073 | Q34: =O34/$O$87 -> 0.57196916
B35: Shareholder #2 | C35: Ordinary (ORD) | E35: 0 | F35: =E35/$E$86 -> 0 | G35: =E35/$E$87 -> 0 | H35: =G35*$C$15 -> 0 | J35: 0 | K35: =ROUND(J35/issue_share_price,0) -> 0 | L35: =IF($K$86=0,0,K35/$K$86) -> 0 | N35: =ROUNDUP(O35*issue_share_price,0) -> 0 | O35: =E35+K35 -> 0 | P35: =O35/$O$86 -> 0 | Q35: =O35/$O$87 -> 0
B36: Shareholder #3 | C36: Ordinary (ORD) | E36: 0 | F36: =E36/$E$86 -> 0 | G36: =E36/$E$87 -> 0 | H36: =G36*$C$15 -> 0 | J36: 0 | K36: =ROUND(J36/issue_share_price,0) -> 0 | L36: =IF($K$86=0,0,K36/$K$86) -> 0 | N36: =ROUNDUP(O36*issue_share_price,0) -> 0 | O36: =E36+K36 -> 0 | P36: =O36/$O$86 -> 0 | Q36: =O36/$O$87 -> 0
B37: Shareholder #4 | C37: Ordinary (ORD) | E37: 0 | F37: =E37/$E$86 -> 0 | G37: =E37/$E$87 -> 0 | H37: =G37*$C$15 -> 0 | J37: 0 | K37: =ROUND(J37/issue_share_price,0) -> 0 | L37: =IF($K$86=0,0,K37/$K$86) -> 0 | N37: =ROUNDUP(O37*issue_share_price,0) -> 0 | O37: =E37+K37 -> 0 | P37: =O37/$O$86 -> 0 | Q37: =O37/$O$87 -> 0
B38: Shareholder #5 | C38: Ordinary (ORD) | E38: 0 | F38: =E38/$E$86 -> 0 | G38: =E38/$E$87 -> 0 | H38: =G38*$C$15 -> 0 | J38: 0 | K38: =ROUND(J38/issue_share_price,0) -> 0 | L38: =IF($K$86=0,0,K38/$K$86) -> 0 | N38: =ROUNDUP(O38*issue_share_price,0) -> 0 | O38: =E38+K38 -> 0 | P38: =O38/$O$86 -> 0 | Q38: =O38/$O$87 -> 0
B39: Shareholder #6 | C39: Ordinary (ORD) | E39: 0 | F39: =E39/$E$86 -> 0 | G39: =E39/$E$87 -> 0 | H39: =G39*$C$15 -> 0 | J39: 0 | K39: =ROUND(J39/issue_share_price,0) -> 0 | L39: =IF($K$86=0,0,K39/$K$86) -> 0 | N39: =ROUNDUP(O39*issue_share_price,0) -> 0 | O39: =E39+K39 -> 0 | P39: =O39/$O$86 -> 0 | Q39: =O39/$O$87 -> 0
B40: Shareholder #7 | C40: Ordinary (ORD) | E40: 0 | F40: =E40/$E$86 -> 0 | G40: =E40/$E$87 -> 0 | H40: =G40*$C$15 -> 0 | J40: 0 | K40: =ROUND(J40/issue_share_price,0) -> 0 | L40: =IF($K$86=0,0,K40/$K$86) -> 0 | N40: =ROUNDUP(O40*issue_share_price,0) -> 0 | O40: =E40+K40 -> 0 | P40: =O40/$O$86 -> 0 | Q40: =O40/$O$87 -> 0
B41: Shareholder #8 | C41: Ordinary (ORD) | E41: 0 | F41: =E41/$E$86 -> 0 | G41: =E41/$E$87 -> 0 | H41: =G41*$C$15 -> 0 | J41: 0 | K41: =ROUND(J41/issue_share_price,0) -> 0 | L41: =IF($K$86=0,0,K41/$K$86) -> 0 | N41: =ROUNDUP(O41*issue_share_price,0) -> 0 | O41: =E41+K41 -> 0 | P41: =O41/$O$86 -> 0 | Q41: =O41/$O$87 -> 0
B42: Shareholder #9 | C42: Ordinary (ORD) | E42: 0 | F42: =E42/$E$86 -> 0 | G42: =E42/$E$87 -> 0 | H42: =G42*$C$15 -> 0 | J42: 0 | K42: =ROUND(J42/issue_share_price,0) -> 0 | L42: =IF($K$86=0,0,K42/$K$86) -> 0 | N42: =ROUNDUP(O42*issue_share_price,0) -> 0 | O42: =E42+K42 -> 0 | P42: =O42/$O$86 -> 0 | Q42: =O42/$O$87 -> 0
B43: Shareholder #10 | C43: Ordinary (ORD) | E43: 0 | F43: =E43/$E$86 -> 0 | G43: =E43/$E$87 -> 0 | H43: =G43*$C$15 -> 0 | J43: 0 | K43: =ROUND(J43/issue_share_price,0) -> 0 | L43: =IF($K$86=0,0,K43/$K$86) -> 0 | N43: =ROUNDUP(O43*issue_share_price,0) -> 0 | O43: =E43+K43 -> 0 | P43: =O43/$O$86 -> 0 | Q43: =O43/$O$87 -> 0
B45: New shareholders | F45: =SUM(F46:F60) -> 0 | G45: =SUM(G46:G60) -> 0 | H45: =SUM(H46:H60) -> 0 | J45: =SUM(J46:J60) -> 1000000 | K45: =SUM(K46:K60) -> 291392 | L45: =SUM(L46:L60) -> 1 | N45: =SUM(N46:N60) -> 999999.07 | O45: =SUM(O46:O60) -> 291392 | P45: =SUM(P46:P60) -> 0.19775339 | Q45: =SUM(Q46:Q60) -> 0.16666724
B46: Investor #1 | C46: Seed Preference (SPRF) | F46: =E46/$E$86 -> 0 | G46: =E46/$E$87 -> 0 | H46: =G46*$C$15 -> 0 | J46: 1000000 | K46: =ROUND(J46/issue_share_price,0) -> 291392 | L46: =IF($K$86=0,0,K46/$K$86) -> 1 | N46: =ROUND(O46*issue_share_price,2) -> 999999.07 | O46: =K46 -> 291392 | P46: =O46/$O$86 -> 0.19775339 | Q46: =O46/$O$87 -> 0.16666724
...

Sheet Lists
B5: Share class code
B7: This list could be made to match that available on ASIC form 484 and thus on ASIC searches.
B8: http://asic.gov.au/for-business/running-a-company/shares/
B9: However, note that it is possible to enter one's own code on Form 484 so others may appear in practice (the code had no impact on the calcuations).
B11: Share class code | C11: Full title | D11: List name
B12: SPRF | C12: Seed Preference | D12: =C12&" ("&B12&")" -> Seed Preference (SPRF)
B13: ORD | C13: Ordinary | D13: =C13&" ("&B13&")" -> Ordinary (ORD)
B14: APRF | C14: Series A Preference | D14: =C14&" ("&B14&")" -> Series A Preference (APRF)
B15: BPRF | C15: Series B Preference | D15: =C15&" ("&B15&")" -> Series B Preference (BPRF)
B16: CPRF | C16: Series C Preference | D16: =C16&" ("&B16&")" -> Series C Preference (CPRF)
B19: Yes/No
B20: Yes
B21: No
B24: Convertible Note Conversion Methods
B25: Pre-money
B26: Post-money
B27: Dollars-invested
B35: Convertible Note interim calculations
B37: Calculations if convertible note converts as part of the raise ("Included")
B39: Cap/discount combination | D39: NewProp
B40: (1) Both notes convert at their respective discount | D40: =(new_money + CN1_value / (1 - CN1_disc) + CN2_value / (1 - CN2_disc) ) / pre_money -> 0.37142857
B41: (2) Both notes convert under their respective cap | D41: =new_money / pre_money + ('Cap Table'!C15/pre_money)*(CN1_value / CN1_cap + CN2_value / CN2_cap) -> 0.37142857
B42: (3) C1 converts at its discount, C2 under its cap | D42: =(new_money + CN1_value / (1 - CN1_disc) + CN2_value * ('Cap Table'!C15 / CN2_cap) ) / pre_money -> 0.37142857
B43: (4) C2 converts at its discount, C1 under its cap | D43: =(new_money + CN1_value * ('Cap Table'!C15 / CN1_cap) + CN2_value / (1 - CN2_disc) ) / pre_money -> 0.37142857
B45: Cap/discount combination | D45: =IF(AND(CN1_disccap="Disc",CN2_disccap="Disc"),1,IF(AND(CN1_disccap="Cap",CN2_disccap="Cap"),2,IF(AND(CN1_disccap="Disc",CN2_disccap="Cap"),3,IF(AND(CN1_disccap="Cap",CN2_disccap="Disc"),4,"Error")))) -> 1
B46: NewProp | D46: {=INDEX(D40:D43,D45)} -> 0.37142857
B47: Post-money ESOP shares (ESOP% on top of existing options) | D47: =post_money_option_pool * (shareholder_shares + optionholder_shares) * ((1 + D$46) / (1 - post_money_option_pool * (1 + D$46))) -> 174834.44
B48: Post-money ESOP shares (ESOP% includes existing options) | D48: =post_money_option_pool * (shareholder_shares) * ((1 + D$46) / (1 - post_money_option_pool * (1 + D$46))) - optionholder_shares -> 58940.397
